Workbook

Sheet Dashboard
A1: x | F1: Financial Dashboard
F2: Income Statement | H2: 2024 | I2: 2025-F | J2: 2026-F | K2: 2027-F
F3: =Charts!H8 -> Revenue | H3: =Charts!J16 -> 7078783.1 | I3: =Charts!K16 -> 14671987 | J3: =Charts!L16 -> 66233629 | K3: =Charts!M16 -> 1.7811425e+08 | N3: =+J3-I3 -> 51561642
G4: =Charts!I9 -> VA Mental Health | H4: =Charts!J9 -> 6970768.1 | I4: =Charts!K9 -> 10955547 | J4: =Charts!L9 -> 17132940 | K4: =Charts!M9 -> 21077100
G5: =Charts!I10 -> VA Medical Exams | H5: =Charts!J10 -> 108015 | I5: =Charts!K10 -> 1040988 | J5: =Charts!L10 -> 4956620 | K5: =Charts!M10 -> 9468620
G6: =Charts!I11 -> Personal Injury | H6: =Charts!J11 -> 0 | I6: =Charts!K11 -> 2547952 | J6: =Charts!L11 -> 27817425 | K6: =Charts!M11 -> 50932946
G7: =Charts!I12 -> Workers Comp | H7: =Charts!J12 -> 0 | I7: =Charts!K12 -> 127500 | J7: =Charts!L12 -> 7650000 | K7: =Charts!M12 -> 19890000
G8: =Charts!I13 -> SaaS | H8: =Charts!J13 -> 0 | I8: =Charts!K13 -> 0 | J8: =Charts!L13 -> 1125419.1 | K8: =Charts!M13 -> 9514199.7
G9: =Charts!I14 -> Corrections | H9: =Charts!J14 -> 0 | I9: =Charts!K14 -> 0 | J9: =Charts!L14 -> 7514100 | K9: =Charts!M14 -> 65531400
G10: =Charts!I15 -> Healthcare Compliance | H10: =Charts!J15 -> 0 | I10: =Charts!K15 -> 0 | J10: =Charts!L15 -> 37125 | K10: =Charts!M15 -> 1699987.5
F11: =Charts!H17 -> COGS | H11: =Charts!J17 -> 4503867 | I11: =Charts!K17 -> 6758123.6 | J11: =Charts!L17 -> 22489378 | K11: =Charts!M17 -> 91956882 | Q11: 26 - $10mm rev growth (all PI)
F12: =Charts!H18 -> Gross Profit | H12: =Charts!J18 -> 2574916.1 | I12: =Charts!K18 -> 7913863.4 | J12: =Charts!L18 -> 43744250 | K12: =Charts!M18 -> 86157371 | Q12: 50% margin on PI - $5mm ($10mm receivable waiting to collect)
G13: =Charts!I19 -> Gross Margin | H13: =Charts!J19 -> 0.36375123 | I13: =Charts!K19 -> 0.53938593 | J13: =Charts!L19 -> 0.66045378 | K13: =Charts!M19 -> 0.48371969 | Q13: QV version - $7.5mm capital / rev growth to PI ($5mm-->$10mm work)
F15: =Charts!H20 -> Expenses | H15: =Charts!J25 -> 1630675 | I15: =Charts!K25 -> 2394328.7 | J15: =Charts!L25 -> 10536978 | K15: =Charts!M25 -> 11217840 | N15: =+J15-I15 -> 8142649.6 | Q15: Risk - make assumption 18 months on receivable vs. 9 months
G16: =Charts!I21 -> Technology | H16: =Charts!J21 -> 171650 | I16: =Charts!K21 -> 182487.04 | J16: =Charts!L21 -> 882042.71 | K16: =Charts!M21 -> 1066909.4
G17: =Charts!I22 -> Marketing & Development | H17: =Charts!J22 -> 534189 | I17: =Charts!K22 -> 346185.62 | J17: =Charts!L22 -> 3995196.5 | K17: =Charts!M22 -> 4223961.5
G18: =Charts!I23 -> Clinical Operations | H18: =Charts!J23 -> 229668 | I18: =Charts!K23 -> 349120.43 | J18: =Charts!L23 -> 2264444.5 | K18: =Charts!M23 -> 1886865.7
G19: =Charts!I24 -> General Administrative | H19: =Charts!J24 -> 695168 | I19: =Charts!K24 -> 1516535.7 | J19: =Charts!L24 -> 3395294.6 | K19: =Charts!M24 -> 4040103
F20: =Charts!H26 -> EBITDA | H20: =Charts!J26 -> 944241.07 | I20: =Charts!K26 -> 5519534.7 | J20: =Charts!L26 -> 33207272 | K20: =Charts!M26 -> 74939531
G21: =Charts!I27 -> EBITDA Margin | H21: =Charts!J27 -> 0.13339031 | I21: =Charts!K27 -> 0.37619544 | J21: =Charts!L27 -> 0.50136574 | K21: =Charts!M27 -> 0.42073854
F23: Balance Sheet | H23: 2024 | I23: 2025-F | J23: 2026-F | K23: 2027-F
F24: Assets | H24: =Charts!J32 -> 1258371 | I24: =Charts!K32 -> 7514289.2 | J24: =Charts!L32 -> 42780908 | K24: =Charts!M32 -> 1.237906e+08
G25: =Charts!I33 -> Cash | H25: =Charts!J33 -> 1257232 | I25: =Charts!K33 -> 2602593.6 | J25: =Charts!L33 -> 11389945 | K25: =Charts!M33 -> 64205898
G26: =Charts!I34 -> Accounts Receivable | H26: =Charts!J34 -> 0 | I26: =Charts!K34 -> 4907723.6 | J26: =Charts!L34 -> 31388191 | K26: =Charts!M34 -> 59583125
G27: =Charts!I35 -> Fixed Assets | H27: =Charts!J35 -> 1139 | I27: =Charts!K35 -> 3972 | J27: =Charts!L35 -> 2772 | K27: =Charts!M35 -> 1572
F28: Liabilities | H28: =Charts!J36 -> 198133 | I28: =Charts!K36 -> 2492984.6 | J28: =Charts!L36 -> 13345037 | K28: =Charts!M36 -> 33412669
G29: =Charts!I37 -> Current Liabilities | H29: =Charts!J37 -> 82446 | I29: =Charts!K37 -> 2446827.6 | J29: =Charts!L37 -> 13308156 | K29: =Charts!M37 -> 33385352
G30: =Charts!I38 -> Long-Term Liabilities | H30: =Charts!J38 -> 115687 | I30: =Charts!K38 -> 46157 | J30: =Charts!L38 -> 36881 | K30: =Charts!M38 -> 27317
F31: Equity | H31: =Charts!J39 -> 1060238 | I31: =Charts!K39 -> 5021304.5 | J31: =Charts!L39 -> 29435871 | K31: =Charts!M39 -> 90377926
F32: =Charts!H41 -> LIABILITIES AND EQUITY | H32: =Charts!J41 -> 1258371 | I32: =Charts!K41 -> 7514289.2 | J32: =Charts!L41 -> 42780908 | K32: =Charts!M41 -> 1.237906e+08

Sheet Monthly Financial Reports
B2: Profit & Loss Forecast
E3: 45292 | F3: 45323 | G3: 45352 | H3: 45383 | I3: 45413 | J3: 45444 | K3: 45474 | L3: 45505 | M3: 45536 | N3: 45566 | O3: 45597 | P3: 45627 | Q3: 45658 | R3: 45689 | S3: 45717 | T3: 45748 | U3: 45778 | V3: 45809 | W3: 45839 | X3: 45870 | Y3: 45901 | Z3: 45931 | AA3: 45962 | AB3: 45992 | AC3: 46023 | AD3: 46054 | AE3: 46082 | AF3: 46113 | AG3: 46143 | AH3: 46174 | AI3: 46204 | AJ3: 46235 | AK3: 46266 | AL3: 46296 | AM3: 46327 | AN3: 46357 | AO3: 46388 | AP3: 46419 | AQ3: 46447 | AR3: 46478 | AS3: 46508 | AT3: 46539 | AU3: 46569 | AV3: 46600 | AW3: 46631 | AX3: 46661 | AY3: 46692 | AZ3: 46722 | BB3: 2024 | BC3: 2025 | BD3: 2026 | BE3: 2027
C5: Revenue | E5: =SUM(E6:E7) -> 399264.35 | F5: =SUM(F6:F7) -> 416954.21 | G5: =SUM(G6:G7) -> 533761.66 | H5: =SUM(H6:H7) -> 540967.64 | I5: =SUM(I6:I7) -> 633262.09 | J5: =SUM(J6:J7) -> 604119.44 | K5: =SUM(K6:K7) -> 557899.1 | L5: =SUM(L6:L7) -> 693490.47 | ... P5: =SUM(P6:P7) -> 623942.57 | Q5: =SUM(Q6:Q13) -> 697873 | R5: =SUM(R6:R13) -> 605304 | S5: =SUM(S6:S13) -> 937772 | T5: =SUM(T6:T13) -> 850512 | U5: =SUM(U6:U13) -> 991397 | V5: =SUM(V6:V13) -> 951240 | W5: =SUM(W6:W13) -> 1034942.6 | X5: =SUM(X6:X13) -> 1263146.6 | ... AZ5: =SUM(AZ6:AZ13) -> 22051622 | BB5: =SUM(BB6:BB13) -> 7078783.1 | BC5: =SUM(BC6:BC13) -> 14671987 | BD5: =SUM(BD6:BD13) -> 66233629 | BE5: =SUM(BE6:BE13) -> 1.7811425e+08
D6: VA Mental Health | E6: 399264.35 | F6: 416954.21 | G6: 533761.66 | H6: 540967.64 | I6: 633262.09 | J6: 603034.44 | K6: 551879.1 | L6: 676335.47 | M6: 593998.91 | N6: 630918.38 | O6: 793259.25 | P6: 597132.57 | Q6: 666495 | R6: 567214 | S6: 880372 | T6: 775302 | U6: 863492 | V6: 721755 | W6: 735947 | X6: =Worksheet!N178 -> 1019370 | Y6: =Worksheet!O178 -> 1167210 | Z6: =Worksheet!P178 -> 1100220 | AA6: =Worksheet!Q178 -> 1208460 | AB6: =Worksheet!R178 -> 1249710 | AC6: =Worksheet!S178 -> 1277100 | AD6: =Worksheet!T178 -> 1304490 | AE6: =Worksheet!U178 -> 1331880 | ... AZ6: =Worksheet!AP178 -> 1907070 | BB6: =SUM(E6:P6) -> 6970768.1 | BC6: =SUM(Q6:AB6) -> 10955547 | BD6: =SUM(AC6:AN6) -> 17132940 | BE6: =SUM(AO6:AZ6) -> 21077100
D7: VA Medical Exams | J7: 1085 | K7: 6020 | L7: 17155 | M7: 18335 | N7: 14200 | O7: 24410 | P7: 26810 | Q7: 31378 | R7: 38090 | S7: 57400 | T7: 63200 | U7: 69600 | V7: 78800 | W7: 84000 | X7: =Worksheet!N179 -> 81780 | Y7: =Worksheet!O179 -> 84835 | Z7: =Worksheet!P179 -> 91885 | AA7: =Worksheet!Q179 -> 150635 | AB7: =Worksheet!R179 -> 209385 | AC7: =Worksheet!S179 -> 240718.33 | AD7: =Worksheet!T179 -> 272051.67 | AE7: =Worksheet!U179 -> 303385 | ... AZ7: =Worksheet!AP179 -> 961385 | BB7: =SUM(E7:P7) -> 108015 | BC7: =SUM(Q7:AB7) -> 1040988 | BD7: =SUM(AC7:AN7) -> 4956620 | BE7: =SUM(AO7:AZ7) -> 9468620
D8: Personal Injury | Q8: 0 | R8: 0 | S8: 0 | T8: 12010 | U8: 58305 | V8: =221000-U8-T8 -> 150685 | W8: =Worksheet!M181 -> 214995.6 | X8: =Worksheet!N181 -> 161996.6 | Y8: =Worksheet!O181 -> 284994.2 | Z8: =Worksheet!P181 -> 400991.8 | AA8: =Worksheet!Q181 -> 579988 | AB8: =Worksheet!R181 -> 683985.8 | AC8: =Worksheet!S181 -> 968980 | AD8: =Worksheet!T181 -> 1246974.2 | ... AZ8: =Worksheet!AP181 -> 4755901.6 | BC8: =SUM(Q8:AB8) -> 2547952 | BD8: =SUM(AC8:AN8) -> 27817425 | BE8: =SUM(AO8:AZ8) -> 50932946
D9: Workers Comp | Q9: 0 | R9: 0 | S9: 0 | T9: 0 | U9: 0 | V9: 0 | W9: =Worksheet!M182 -> 0 | X9: =Worksheet!N182 -> 0 | Y9: =Worksheet!O182 -> 0 | Z9: =Worksheet!P182 -> 0 | AA9: =Worksheet!Q182 -> 42500 | AB9: =Worksheet!R182 -> 85000 | AC9: =Worksheet!S182 -> 170000 | AD9: =Worksheet!T182 -> 255000 | ... AZ9: =Worksheet!AP182 -> 2125000 | BC9: =SUM(Q9:AB9) -> 127500 | BD9: =SUM(AC9:AN9) -> 7650000 | BE9: =SUM(AO9:AZ9) -> 19890000
D10: SaaS | Q10: 0 | R10: 0 | S10: 0 | T10: 0 | U10: 0 | V10: 0 | W10: =Worksheet!M188 -> 0 | X10: =Worksheet!N188 -> 0 | Y10: =Worksheet!O188 -> 0 | Z10: =Worksheet!P188 -> 0 | AA10: =Worksheet!Q188 -> 0 | AB10: =Worksheet!R188 -> 0 | AC10: =Worksheet!S188 -> 0 | AD10: =Worksheet!T188 -> 0 | ... AZ10: =Worksheet!AP188 -> 1327665.6 | BC10: =SUM(Q10:AB10) -> 0 | BD10: =SUM(AC10:AN10) -> 1125419.1 | BE10: =SUM(AO10:AZ10) -> 9514199.7
D11: Corrections | Q11: 0 | R11: 0 | S11: 0 | T11: 0 | U11: 0 | V11: 0 | W11: =Worksheet!M184 -> 0 | X11: =Worksheet!N184 -> 0 | Y11: =Worksheet!O184 -> 0 | Z11: =Worksheet!P184 -> 0 | AA11: =Worksheet!Q184 -> 0 | AB11: =Worksheet!R184 -> 0 | AC11: =Worksheet!S184 -> 0 | AD11: =Worksheet!T184 -> 0 | ... AZ11: =Worksheet!AP184 -> 10711800 | BC11: =SUM(Q11:AB11) -> 0 | BD11: =SUM(AC11:AN11) -> 7514100 | BE11: =SUM(AO11:AZ11) -> 65531400
D12: Healthcare Compliance | Q12: 0 | R12: 0 | S12: 0 | T12: 0 | U12: 0 | V12: 0 | W12: 0 | X12: 0 | Y12: 0 | Z12: 0 | AA12: 0 | AB12: 0 | AC12: 0 | AD12: 0 | AE12: 0 | AF12: 0 | AG12: 0 | AH12: 0 | AI12: =Worksheet!Y185 -> 0 | AJ12: =Worksheet!Z185 -> 0 | AK12: =Worksheet!AA185 -> 0 | AL12: =Worksheet!AB185 -> 6187.5 | AM12: =Worksheet!AC185 -> 12375 | AN12: =Worksheet!AD185 -> 18562.5 | AO12: =Worksheet!AE185 -> 41062.5 | AP12: =Worksheet!AF185 -> 57487.5 | ... AZ12: =Worksheet!AP185 -> 262800 | BC12: =SUM(Q12:AB12) -> 0 | BD12: =SUM(AC12:AN12) -> 37125 | BE12: =SUM(AO12:AZ12) -> 1699987.5
D13: Employee Wellness | Q13: 0 | R13: 0 | S13: 0 | T13: 0 | U13: 0 | V13: 0 | W13: =Worksheet!M186 -> 0 | X13: =Worksheet!N186 -> 0 | Y13: =Worksheet!O186 -> 0 | Z13: =Worksheet!P186 -> 0 | AA13: =Worksheet!Q186 -> 0 | AB13: =Worksheet!R186 -> 0 | AC13: =Worksheet!S186 -> 0 | AD13: =Worksheet!T186 -> 0 | ... AZ13: =Worksheet!AP186 -> 0 | BC13: =SUM(AM13:AX13) -> 0 | BD13: =SUM(AN13:AY13) -> 0 | BE13: =SUM(AO13:AZ13) -> 0
C15: COGS | Q15: 424809.87 | R15: 428219.25 | S15: 642221.25 | T15: 708475.86 | U15: 504172.01 | V15: 578488.93 | W15: 498680 | X15: 488960 | Y15: 513791 | Z15: 540930 | AA15: =Z15*AA5/Z5 -> 672839.02 | AB15: =AA15*AB5/AA5 -> 756536.42 | AC15: =AB15*AC5/AB5 -> 902105.84 | AD15: =AC15*AD5/AC5 -> 1045298.4 | AE15: =AD15*AE5/AD5 -> 1186793.4 | AF15: =AE15*AF5/AE5 -> 1324213.8 | AG15: =AF15*AG5/AF5 -> 1459257.4 | AH15: =AG15*AH5/AG5 -> 1602657.1 | ... AT15: =AS15*AT5/AS5 -> 4543005.3 | AU15: =Worksheet!AK85 -> 8204744 | AV15: =Worksheet!AL85 -> 10735816 | AW15: =Worksheet!AM85 -> 11617282 | AX15: =Worksheet!AN85 -> 11767926 | AY15: =Worksheet!AO85 -> 11922303 | AZ15: =AY15*AZ5/AY5 -> 13957141 | BB15: 4503867 | BC15: =SUM(Q15:AB15) -> 6758123.6 | BD15: =SUM(AC15:AN15) -> 22489378 | BE15: =SUM(AO15:AZ15) -> 91956882
C17: Gross Profit | Q17: =Q5-Q15 -> 273063.13 | R17: =R5-R15 -> 177084.75 | S17: =S5-S15 -> 295550.75 | T17: =T5-T15 -> 142036.14 | U17: =U5-U15 -> 487224.99 | V17: =V5-V15 -> 372751.07 | W17: =W5-W15 -> 536262.6 | X17: =X5-X15 -> 774186.6 | ... AZ17: =AZ5-AZ15 -> 8094480.8 | BB17: =BB5-BB15 -> 2574916.1 | BC17: =SUM(Q17:AB17) -> 7913863.4 | BD17: =BD5-BD15 -> 43744250 | BE17: =BE5-BE15 -> 86157371
D18: Gross Margin | Q18: =Q17/Q5 -> 0.39127912 | R18: =R17/R5 -> 0.29255506 | S18: =S17/S5 -> 0.3151627 | T18: =T17/T5 -> 0.16700075 | U18: =U17/U5 -> 0.49145296 | V18: =V17/V5 -> 0.39185807 | W18: =W17/W5 -> 0.51815685 | X18: =X17/X5 -> 0.61290321 | ... AZ18: =AZ17/AZ5 -> 0.36706963 | BB18: =BB17/BB5 -> 0.36375123 | BC18: =BC17/BC5 -> 0.53938593 | BD18: =BD17/BD5 -> 0.66045378 | BE18: =BE17/BE5 -> 0.48371969
C20: Expenses | Q20: =SUM(Q21:Q24) -> 174662.01 | R20: =SUM(R21:R24) -> 414778.49 | S20: =SUM(S21:S24) -> 199025.41 | T20: =SUM(T21:T24) -> 207571.94 | U20: =SUM(U21:U24) -> 32636.833 | V20: =SUM(V21:V24) -> 205117.9 | W20: =SUM(W21:W24) -> 175297.17 | X20: =SUM(X21:X24) -> 181987.5 | ... AZ20: =SUM(AZ21:AZ24) -> 998254.1 | BB20: =SUM(BB21:BB24) -> 1630675 | BC20: =SUM(Q20:AB20) -> 2394328.7 | BD20: =SUM(BD21:BD24) -> 10536978 | BE20: =SUM(BE21:BE24) -> 11217840
D21: Technology | Q21: 14719.81 | R21: 13757.56 | S21: 28920.28 | T21: 26873.24 | U21: 17173.83 | V21: 14673.57 | W21: =Worksheet!M26 -> 7728.125 | X21: =Worksheet!N26 -> 7728.125 | Y21: =Worksheet!O26 -> 7728.125 | Z21: =Worksheet!P26 -> 7728.125 | AA21: =Worksheet!Q26 -> 17728.125 | AB21: =Worksheet!R26 -> 17728.125 | AC21: =Worksheet!S26 -> 73184.375 | AD21: =Worksheet!T26 -> 48640.625 | ... AZ21: =Worksheet!AP26 -> 97796.458 | BB21: =96650+75000 -> 171650 | BC21: =SUM(Q21:AB21) -> 182487.04 | BD21: =SUM(AC21:AN21) -> 882042.71 | BE21: =SUM(AO21:AZ21) -> 1066909.4
D22: Marketing & Development | Q22: 31414.513 | R22: 32500.673 | S22: 48808.563 | T22: 31705.483 | U22: 21617.503 | V22: 22794.253 | W22: =Worksheet!M32 -> 26224.104 | X22: =Worksheet!N32 -> 26224.104 | Y22: =Worksheet!O32 -> 26224.104 | Z22: =Worksheet!P32 -> 26224.104 | AA22: =Worksheet!Q32 -> 26224.104 | AB22: =Worksheet!R32 -> 26224.104 | AC22: =Worksheet!S32 -> 147300.98 | AD22: =Worksheet!T32 -> 242300.98 | ... AZ22: =Worksheet!AP32 -> 318903.48 | BB22: =384189+150000 -> 534189 | BC22: =SUM(Q22:AB22) -> 346185.62 | BD22: =SUM(AC22:AN22) -> 3995196.5 | BE22: =SUM(AO22:AZ22) -> 4223961.5
D23: Clinical Operations | Q23: 26394.744 | R23: 26484.744 | S23: 26484.744 | T23: 26525.064 | U23: 26771.444 | V23: 26615.064 | W23: =Worksheet!M48 -> 26224.104 | X23: =Worksheet!N48 -> 26224.104 | Y23: =Worksheet!O48 -> 26224.104 | Z23: =Worksheet!P48 -> 26224.104 | AA23: =Worksheet!Q48 -> 26224.104 | AB23: =Worksheet!R48 -> 58724.104 | AC23: =Worksheet!S48 -> 125600.28 | AD23: =Worksheet!T48 -> 200600.28 | ... AZ23: =Worksheet!AP48 -> 234562.16 | BB23: =17668+212000 -> 229668 | BC23: =SUM(Q23:AB23) -> 349120.43 | BD23: =SUM(AC23:AN23) -> 2264444.5 | BE23: =SUM(AO23:AZ23) -> 1886865.7
D24: General Administrative | Q24: 102132.94 | R24: 342035.51 | S24: 94811.824 | T24: 122468.15 | U24: -32925.944 | V24: 141035.01 | W24: =Worksheet!M56 -> 115120.83 | X24: =Worksheet!N56 -> 121811.17 | Y24: =Worksheet!O56 -> 122731.17 | Z24: =Worksheet!P56 -> 128185 | AA24: =Worksheet!Q56 -> 129105 | AB24: =Worksheet!R56 -> 130025 | AC24: =Worksheet!S56 -> 261890.96 | AD24: =Worksheet!T56 -> 270519.08 | ... AZ24: =Worksheet!AP56 -> 346992 | BB24: =1651983-BB21-BB22-BB23-BB29-BB31-BB32 -> 695168 | BC24: =SUM(Q24:AB24) -> 1516535.7 | BD24: =SUM(AC24:AN24) -> 3395294.6 | BE24: =SUM(AO24:AZ24) -> 4040103
C26: EBITDA | Q26: =Q17-Q20 -> 98401.12 | R26: =R17-R20 -> -237693.74 | S26: =S17-S20 -> 96525.34 | T26: =T17-T20 -> -65535.8 | U26: =U17-U20 -> 454588.16 | V26: =V17-V20 -> 167633.18 | W26: =W17-W20 -> 360965.43 | X26: =X17-X20 -> 592199.1 | ... AZ26: =AZ17-AZ20 -> 7096226.7 | BB26: =BB17-BB20 -> 944241.07 | BC26: =BC17-BC20 -> 5519534.7 | BD26: =BD17-BD20 -> 33207272 | BE26: =BE17-BE20 -> 74939531
D27: EBIT Margin | Q27: =Q26/Q$5 -> 0.14100147 | R27: =R26/R$5 -> -0.3926849 | S27: =S26/S$5 -> 0.1029305 | T27: =T26/T$5 -> -0.077054527 | U27: =U26/U$5 -> 0.45853292 | V27: =V26/V$5 -> 0.17622596 | W27: =W26/W$5 -> 0.34877822 | X27: =X26/X5 -> 0.46882848 | Y27: =Y26/Y5 -> 0.54672691 | Z27: =Z26/Z5 -> 0.54221782 | AA27: =AA26/AA5 -> 0.55988704 | AB27: =AB26/AB5 -> 0.55601352 | AC27: =AC26/AC5 -> 0.43161571 | AD27: =AD26/AD5 -> 0.4129121 | AE27: =AE26/AE5 -> 0.38308214 | ... AZ27: =AZ26/AZ5 -> 0.32180067 | BB27: =BB26/BB5 -> 0.13339031 | BC27: =BC26/BC5 -> 0.37619544 | BD27: =BD26/BD5 -> 0.50136574 | BE27: =BE26/BE5 -> 0.42073854
D29: Interest Expense | Q29: 750 | R29: 750 | S29: 750 | T29: 750 | U29: 750 | V29: 750 | W29: 750 | X29: =W29-2 -> 748 | Y29: =X29-2 -> 746 | Z29: =Y29-2 -> 744 | AA29: =Z29-2 -> 742 | AB29: =AA29-2 -> 740 | AC29: =AB29-2 -> 738 | AD29: =AC29-2 -> 736 | AE29: =AD29-2 -> 734 | ... AZ29: =AY29-2 -> 692 | BB29: 11108 | BC29: =SUM(Q29:AB29) -> 8970 | BD29: =SUM(AC29:AN29) -> 8724 | BE29: =SUM(AO29:AZ29) -> 8436
A30: 0.259 | D30: Income Tax | W30: =$A30*W26 -> 93490.047 | X30: =$A30*X26 -> 153379.57 | Y30: =$A30*Y26 -> 217648.24 | Z30: =$A30*Z26 -> 223725.62 | AA30: =$A30*AA26 -> 287350.83 | AB30: =$A30*AB26 -> 320860.35 | AC30: =$A30*AC26 -> 296999.42 | AD30: =$A30*AD26 -> 329229.52 | ... AZ30: =$A30*AZ26 -> 1837922.7 | BC30: =SUM(Q30:AB30) -> 1296454.6 | BD30: =SUM(AC30:AN30) -> 8600683.4 | BE30: =SUM(AO30:AZ30) -> 19409339
D31: Depreciation | Q31: 100 | R31: 100 | S31: 100 | T31: 100 | U31: 100 | V31: 100 | W31: 100 | X31: =W31 -> 100 | Y31: =X31 -> 100 | Z31: =Y31 -> 100 | AA31: =Z31 -> 100 | AB31: =AA31 -> 100 | AC31: =AB31 -> 100 | AD31: =AC31 -> 100 | AE31: =AD31 -> 100 | ... AZ31: =AY31 -> 100 | BB31: 1200 | BC31: =SUM(Q31:AB31) -> 1200 | BD31: =SUM(AC31:AN31) -> 1200 | BE31: =SUM(AO31:AZ31) -> 1200
D32: Amortization | Q32: =1500-Q29 -> 750 | R32: =1500-R29 -> 750 | S32: =1500-S29 -> 750 | T32: =1500-T29 -> 750 | U32: =1500-U29 -> 750 | V32: =1500-V29 -> 750 | W32: =1500-W29 -> 750 | X32: =1500-X29 -> 752 | ... AZ32: =1500-AZ29 -> 808 | BB32: 9000 | BC32: =SUM(Q32:AB32) -> 9030 | BD32: =SUM(AC32:AN32) -> 9276 | BE32: =SUM(AO32:AZ32) -> 9564
C34: Net Income | Q34: =Q26-SUM(Q29:Q32) -> 96801.12 | R34: =R26-SUM(R29:R32) -> -239293.74 | S34: =S26-SUM(S29:S32) -> 94925.34 | T34: =T26-SUM(T29:T32) -> -67135.8 | U34: =U26-SUM(U29:U32) -> 452988.16 | V34: =V26-SUM(V29:V32) -> 166033.18 | W34: =W26-SUM(W29:W32) -> 265875.39 | X34: =X26-SUM(X29:X32) -> 437219.53 | ... AZ34: =AZ26-SUM(AZ29:AZ32) -> 5256704 | BB34: =BB26-SUM(BB29:BB32) -> 922933.07 | BC34: =BC26-SUM(BC29:BC32) -> 4203880 | BD34: =BD26-SUM(BD29:BD32) -> 24587389 | BE34: =BE26-SUM(BE29:BE32) -> 55510993
D35: Net Margin | Q35: =Q34/Q$5 -> 0.13870879 | R35: =R34/R$5 -> -0.3953282 | S35: =S34/S$5 -> 0.10122433 | T35: =T34/T$5 -> -0.078935747 | U35: =U34/U$5 -> 0.45691903 | V35: =V34/V$5 -> 0.17454394 | W35: =W34/W$5 -> 0.25689868 | X35: =X34/X$5 -> 0.34613523 | ... AZ35: =AZ34/AZ$5 -> 0.23838174 | BB35: =BB34/BB$5 -> 0.13038019 | BC35: =BC34/BC$5 -> 0.28652425 | BD35: =BD34/BD$5 -> 0.37122213 | BE35: =BE34/BE$5 -> 0.31165946
B38: Cashflow Forecast
Q39: 45658 | R39: 45689 | S39: 45717 | T39: 45748 | U39: 45778 | V39: 45809 | W39: 45839 | X39: 45870 | Y39: 45901 | Z39: 45931 | AA39: 45962 | AB39: 45992 | AC39: 46023 | AD39: 46054 | AE39: 46082 | AF39: 46113 | AG39: 46143 | AH39: 46174 | AI39: 46204 | AJ39: 46235 | AK39: 46266 | AL39: 46296 | AM39: 46327 | AN39: 46357 | AO39: 46388 | AP39: 46419 | AQ39: 46447 | AR39: 46478 | AS39: 46508 | AT39: 46539 | AU39: 46569 | AV39: 46600 | AW39: 46631 | AX39: 46661 | AY39: 46692 | AZ39: 46722 | BB39: 2024 | BC39: 2025 | BD39: 2026 | BE39: 2027
C41: Starting Cash | Q41: 1257232 | R41: =Q58 -> 1337303.1 | S41: =R58 -> 1111183.4 | T41: =S58 -> 1210604.1 | U41: =T58 -> 615697.93 | V41: =U58 -> 985758.14 | W41: =V58 -> 994792.37 | X41: =W58 -> 907889.66 | Y41: =X58 -> 1040575.4 | ... AZ41: =AY58 -> 57776987 | BB41: 299151 | BC41: =BB58 -> 1257232.1 | BD41: =AC41 -> 2602593.6 | BE41: =AO41 -> 11389945
D43: Net Income | Q43: =Q34 -> 96801.12 | R43: =R34 -> -239293.74 | S43: =S34 -> 94925.34 | T43: =T34 -> -67135.8 | U43: =U34 -> 452988.16 | V43: =V34 -> 166033.18 | W43: =W34 -> 265875.39 | X43: =X34 -> 437219.53 | ... AZ43: =AZ34 -> 5256704 | BB43: =BB34 -> 922933.07 | BC43: =SUM(Q43:AB43) -> 4203880 | BD43: =SUM(AC43:AN43) -> 24587389 | BE43: =SUM(AO43:AZ43) -> 55510993
D44: Recievables | T44: =-T8 -> -12010 | U44: =-U8 -> -58305 | V44: =-V8 -> -150685 | W44: =-Worksheet!M121 -> -1012535.3 | X44: =-Worksheet!N121 -> -1263146.6 | Y44: =-Worksheet!O121 -> -1537039.2 | Z44: =-Worksheet!P121 -> -1593096.8 | AA44: =-Worksheet!Q121 -> -1981583 | AB44: =-Worksheet!R121 -> -2228080.8 | AC44: =-Worksheet!S121 -> -2656798.3 | AD44: =-Worksheet!T121 -> -3078515.9 | ... AZ44: =-Worksheet!AP121 -> -20723957 | BC44: =SUM(Q44:AB44) -> -9836481.7 | BD44: =SUM(AC44:AN44) -> -65108210 | BE44: =SUM(AO44:AZ44) -> -1.6860005e+08
D45: Payables - COGS | W45: =Worksheet!M143 -> 512450.74 | X45: =Worksheet!N143 -> 642295 | Y45: =Worksheet!O143 -> 775265 | Z45: =Worksheet!P143 -> 792840 | AA45: =Worksheet!Q143 -> 974540 | AB45: =Worksheet!R143 -> 1088115 | AC45: =Worksheet!S143 -> 1286440 | AD45: =Worksheet!T143 -> 1481765 | ... AZ45: =Worksheet!AP143 -> 13913755 | BB45: 24948 | BC45: =SUM(Q45:AB45) -> 4785505.7 | BD45: =SUM(AC45:AN45) -> 33945930 | BE45: =SUM(AO45:AZ45) -> 105563495
D46: Net Contribution Cash | Q46: -22412 | R46: 2113 | S46: -39368 | T46: 3983 | U46: 345 | V46: -1269 | W46: =Worksheet!M117 -> 25449.146 | X46: =Worksheet!N117 -> 180381.63 | Y46: =Worksheet!O117 -> 265921.55 | Z46: =Worksheet!P117 -> 352096.71 | AA46: =Worksheet!Q117 -> 378001.71 | AB46: =Worksheet!R117 -> 223976.71 | AC46: =Worksheet!S117 -> 292739.42 | AD46: =Worksheet!T117 -> 270612.12 | ... AZ46: =Worksheet!AP117 -> 6148968.8 | BC46: =SUM(Q46:AB46) -> 1369219.4 | BD46: =SUM(AC46:AN46) -> 8083934 | BE46: =SUM(AO46:AZ46) -> 49657860
A47: 0.25 | D47: Net Expense Cash | Q47: =Worksheet!G23*'Monthly Financial Reports'!$A47 -> 0 | R47: =Worksheet!H23*'Monthly Financial Reports'!$A47 -> 0 | S47: =Worksheet!I23*'Monthly Financial Reports'!$A47 -> 12004.354 | T47: =Worksheet!J23*'Monthly Financial Reports'!$A47 -> 3477.6562 | U47: =Worksheet!K23*'Monthly Financial Reports'!$A47 -> 3220.0521 | V47: =Worksheet!L23*'Monthly Financial Reports'!$A47 -> 3220.0521 | W47: =Worksheet!M23*'Monthly Financial Reports'!$A47 -> 23937.25 | X47: =Worksheet!N23*'Monthly Financial Reports'!$A47 -> 1672.5833 | ... AZ47: =Worksheet!AP23*'Monthly Financial Reports'!$A47 -> 10301.042 | BC47: =SUM(Q47:AB47) -> 52085.406 | BD47: =SUM(AC47:AN47) -> 152328 | BE47: =SUM(AO47:AZ47) -> 52675.208
D48: Income Tax | W48: =W30 -> 93490.047 | X48: =X30 -> 153379.57 | Y48: =Y30 -> 217648.24 | Z48: =Z30 -> 223725.62 | AA48: =AA30 -> 287350.83 | AB48: =AB30 -> 320860.35 | AC48: =AC30 -> 296999.42 | AD48: =AD30 -> 329229.52 | ... AZ48: =AZ30 -> 1837922.7 | BC48: =SUM(Q48:AB48) -> 1296454.6 | BD48: =SUM(AC48:AN48) -> 8600683.4 | BE48: =SUM(AO48:AZ48) -> 19409339
D49: Taxes Paid | AF49: =-SUM(Q48:AB48) -> -1296454.6 | AR49: =-SUM(AC48:AN48) -> -8600683.4 | BC49: =SUM(Q49:AB49) -> 0 | BD49: =SUM(AC49:AN49) -> -1296454.6 | BE49: =SUM(AO49:AZ49) -> -8600683.4
D50: Interest Expense | Q50: =-Q29 -> -750 | R50: =-R29 -> -750 | S50: =-S29 -> -750 | T50: =-T29 -> -750 | U50: =-U29 -> -750 | V50: =-V29 -> -750 | W50: =-W29 -> -750 | X50: =-X29 -> -748 | ... AZ50: =-AZ29 -> -692 | BC50: =SUM(Q50:AB50) -> -8970 | BD50: =SUM(AC50:AN50) -> -8724 | BE50: =SUM(AO50:AZ50) -> -8436
D51: Depreciation | Q51: =Q31 -> 100 | R51: =R31 -> 100 | S51: =S31 -> 100 | T51: =T31 -> 100 | U51: =U31 -> 100 | V51: =V31 -> 100 | W51: =W31 -> 100 | X51: =X31 -> 100 | ... AZ51: =AZ31 -> 100 | BB51: =BB31 -> 1200 | BC51: =SUM(Q51:AB51) -> 1200 | BD51: =SUM(AC51:AN51) -> 1200 | BE51: =SUM(AO51:AZ51) -> 1200
D52: Amortization | Q52: =Q32 -> 750 | R52: =R32 -> 750 | S52: =S32 -> 750 | T52: =T32 -> 750 | U52: =U32 -> 750 | V52: =V32 -> 750 | W52: =W32 -> 750 | X52: =X32 -> 752 | ... AZ52: =AZ32 -> 808 | BB52: =BB32 -> 9000 | BC52: =SUM(Q52:AB52) -> 9030 | BD52: =SUM(AC52:AN52) -> 9276 | BE52: =SUM(AO52:AZ52) -> 9564
...

Sheet Assumptions
B1: ASSUMPTIONS:
B3: General:
B4: G1 | C4: The model spans 4 years: 2024 - 2027. It includes both actual and forecasted financials.
B5: G2 | C5: The Financial outputs can be found in the "Dashboard" page highlited in red or the "Monthly Financial Reports" highlited in blue
B6: G3 | C6: The model uses the GAAP-approved acrural accounting method and treats taxes as if the company were a C-corp. At present the company is an S-Corp that manages its books on a cash basis. In transistioning from method to the other, there may be small inconsistencies.
B7: G4 | C7: The model is interactive. All assumption inputs are in boxed yellow cells. Changes to an assumption will flow through the entire model.
B8: G5 | C8: Most of the assumptions and calculations are inputted and performed on the "Worksheet" page highlited in green.
B10: Fund Raise:
B11: FR1 | C11: Input for the capital raised is on line 55 of the "Monthly Financial Reports."
B13: Staffing:
B14: S1 | C14: Staffing details and inputs are on the "Staffing" sheet highlited in yellow
B15: S2 | C15: Employees focused on one specific product are counted as COGS for that product. The remainder are counted as an expense by function.
B16: S3 | C16: The starting dates of all staff counted as COGS are driven by the start date of that product.
B17: S4 | C17: Starting dates for funcitional staff and all salaries are inputted manually on the staffing sheet.
B19: Product Rollout:
B20: PR1 | C20: Starting dates of the product rollout are inputted in Worksheet rows 6-18 and drive the calculations for the rest of the model
B21: PR2 | C21: There is a graphical representation of the rollout as a seperate sheet highlited in pink
B23: Expenses:
B24: EX1 | C24: Functional Expenses and overhead are tracked in Worksheet rows 20-83
B25: EX2 | C25: Most inputs are growth factors to existing expenses
B27: Taxes and Benefits:
B28: TB1 | C28: Payroll tax: 7.65% of gross salary - Input on "Staffing" sheet
B29: TB2 | C29: Average Employee Benefits: 16% of gross salary - Input in "Staffing" sheet.
B30: TB3 | C30: Federal and State Income tax: 25.9% of EBITDA - Input in "Monthly Financial Reports"
B31: TB4 | C31: For simplicity, model shows income taxes paid once a year in April. This is not going to be the case in reality.
B33: Summaries of Revenue, COGS and Accrual Adjustments:
B34: RCC1 | C34: Financial assumptions and calculations are inputted and performed per project in the in "Worksheet"
B35: RCC2 | C35: The Summaries of the Revenue, COGS and Accrual Adjustments are the results of those assumprtions and calculations.
B36: RCC3 | C36: The Summary of COGS is shown in Worksheet rows 85-115
B37: RCC4 | C37: The Summary of Revenues is shown in Worksheet rows 175-192
B38: RCC5 | C38: Accrual adjustments are summarized in Worksheet lines 117-173
B39: RCC6 | C39: The Income Statement is affected by the MONTHLY Receivables and Payables of each Product
B40: RCC7 | C40: The Balance Sheet is affected by MONTHLY Net Cash as well as CUMULATIVE recievables and payables of each product
B42: Product Assumptions and Calculations:
C43: VA Mental Health: Worksheet lines 196-236
C44: - Current product line, broken out by contract, financial assumptions based on actual data
C45: VA Medical Exams: Worksheet lines 238-271
C46: - Current product line, broken out by contract, projected assumptions based on actual data
C47: - Sharp increase in sales driven by addition of Loyal Source contract in August 2025
C48: Personal Injury: Worksheet lines 273-309
...

Sheet Worksheet
G1: 2025 | S1: 2026 | AE1: 2027 | AQ1: 2028 | BD1: Annual
G2: -5 | H2: -4 | I2: -3 | J2: -2 | K2: -1 | L2: 0 | M2: 1 | N2: 2 | O2: 3 | P2: 4 | Q2: 5 | R2: 6 | S2: 7 | T2: 8 | U2: 9 | V2: 10 | W2: 11 | X2: 12 | Y2: 13 | Z2: 14 | AA2: 15 | AB2: 16 | AC2: 17 | AD2: 18 | AE2: 19 | AF2: 20 | AG2: 21 | AH2: 22 | AI2: 23 | AJ2: 24 | AK2: 25 | AL2: 26 | AM2: 27 | AN2: 28 | AO2: 29 | AP2: 30 | AQ2: 31 | AR2: 32 | AS2: 33 | AT2: 34 | AU2: 35 | AV2: 36 | AW2: 37 | AX2: 38 | AY2: 39 | AZ2: 40 | BA2: 41 | BB2: 42
G3: 45658 | H3: 45689 | I3: 45717 | J3: 45748 | K3: 45778 | L3: 45809 | M3: 45839 | N3: 45870 | O3: 45901 | P3: 45931 | Q3: 45962 | R3: 45992 | S3: 46023 | T3: 46054 | U3: 46082 | V3: 46113 | W3: 46143 | X3: 46174 | Y3: 46204 | Z3: 46235 | AA3: 46266 | AB3: 46296 | AC3: 46327 | AD3: 46357 | AE3: 46388 | AF3: 46419 | AG3: 46447 | AH3: 46478 | AI3: 46508 | AJ3: 46539 | AK3: 46569 | AL3: 46600 | AM3: 46631 | AN3: 46661 | AO3: 46692 | AP3: 46722 | AQ3: 46753 | AR3: 46784 | AS3: 46813 | AT3: 46844 | AU3: 46874 | AV3: 46905 | AW3: 46935 | AX3: 46966 | AY3: 46997 | AZ3: 47027 | BA3: 47058 | BB3: 47088 | BD3: 2024 | BE3: 2025 | BF3: 2026 | BG3: 2027
L4: =L2 -> 0 | M4: =M2 -> 1 | N4: =N2 -> 2 | O4: =O2 -> 3 | P4: =P2 -> 4 | Q4: =Q2 -> 5 | R4: =R2 -> 6 | S4: =S2 -> 7 | ... BB4: =BB2 -> 42
A6: Product Rollout
C8: Launch Date | D8: Months Prep | E8: Start Prep
B9: VA - Mental Health | C9: 45292 | G9: =IF($C9<=G$3,1," ") -> 1 | H9: =IF($C9<=H$3,1," ") -> 1 | I9: =IF($C9<=I$3,1," ") -> 1 | J9: =IF($C9<=J$3,1," ") -> 1 | K9: =IF($C9<=K$3,1," ") -> 1 | L9: =IF($C9<=L$3,1," ") -> 1 | M9: =IF($C9<=M$3,1," ") -> 1 | N9: =IF($C9<=N$3,1," ") -> 1 | ... BB9: =IF($C9<=BB$3,1," ") -> 1
B10: VA - Medical Evaluations | C10: 45658 | G10: =IF($C10<=G$3,1," ") -> 1 | H10: =IF($C10<=H$3,1," ") -> 1 | I10: =IF($C10<=I$3,1," ") -> 1 | J10: =IF($C10<=J$3,1," ") -> 1 | K10: =IF($C10<=K$3,1," ") -> 1 | L10: =IF($C10<=L$3,1," ") -> 1 | M10: =IF($C10<=M$3,1," ") -> 1 | N10: =IF($C10<=N$3,1," ") -> 1 | ... BB10: =IF($C10<=BB$3,1," ") -> 1
B11: Personal Injury | C11: 45778 | G11: =IF($C11<=G$3,1," ") | H11: =IF($C11<=H$3,1," ") | I11: =IF($C11<=I$3,1," ") | J11: =IF($C11<=J$3,1," ") | K11: =IF($C11<=K$3,1," ") -> 1 | L11: =IF($C11<=L$3,1," ") -> 1 | M11: =IF($C11<=M$3,1," ") -> 1 | N11: =IF($C11<=N$3,1," ") -> 1 | ... BB11: =IF($C11<=BB$3,1," ") -> 1
B12: Workers Comp | C12: 45931 | D12: 3 | F12: =HLOOKUP(C12,M$3:AP$4,2,FALSE) -> 4 | M12: =IF($C12<=M$3,1," ") | N12: =IF($C12<=N$3,1," ") | O12: =IF($C12<=O$3,1," ") | P12: =IF($C12<=P$3,1," ") -> 1 | Q12: =IF($C12<=Q$3,1," ") -> 1 | R12: =IF($C12<=R$3,1," ") -> 1 | S12: =IF($C12<=S$3,1," ") -> 1 | T12: =IF($C12<=T$3,1," ") -> 1 | ... BB12: =IF($C12<=BB$3,1," ") -> 1
B13: SaaS | C13: 46174 | D13: 3 | F13: =HLOOKUP(C13,M$3:AP$4,2,FALSE) -> 12 | M13: =IF($C13<=M$3,1," ") | N13: =IF($C13<=N$3,1," ") | O13: =IF($C13<=O$3,1," ") | P13: =IF($C13<=P$3,1," ") | Q13: Starting to have expenses | S13: =IF($C13<=S$3,1," ") | T13: =IF($C13<=T$3,1," ") | U13: =IF($C13<=U$3,1," ") | V13: =IF($C13<=V$3,1," ") | W13: =IF($C13<=W$3,1," ") | X13: =IF($C13<=X$3,1," ") -> 1 | Y13: =IF($C13<=Y$3,1," ") -> 1 | Z13: =IF($C13<=Z$3,1," ") -> 1 | ... BB13: =IF($C13<=BB$3,1," ") -> 1
B14: Corrections | C14: 46204 | D14: 3 | F14: =HLOOKUP(C14,M$3:AP$4,2,FALSE) -> 13 | M14: =IF($C14<=M$3,1," ") | N14: =IF($C14<=N$3,1," ") | O14: =IF($C14<=O$3,1," ") | P14: =IF($C14<=P$3,1," ") | Q14: =IF($C14<=Q$3,1," ") | R14: =IF($C14<=R$3,1," ") | S14: =IF($C14<=S$3,1," ") | T14: =IF($C14<=T$3,1," ") | ... BB14: =IF($C14<=BB$3,1," ") -> 1
B15: Healthcare Compliance | C15: 46296 | D15: 3 | F15: =HLOOKUP(C15,M$3:AP$4,2,FALSE) -> 16 | M15: =IF($C15<=M$3,1," ") | N15: =IF($C15<=N$3,1," ") | O15: =IF($C15<=O$3,1," ") | P15: =IF($C15<=P$3,1," ") | Q15: =IF($C15<=Q$3,1," ") | R15: =IF($C15<=R$3,1," ") | S15: =IF($C15<=S$3,1," ") | T15: =IF($C15<=T$3,1," ") | ... BB15: =IF($C15<=BB$3,1," ") -> 1
B16: Employee Wellness | C16: 46753 | D16: 3 | M16: =IF($C16<=M$3,1," ") | N16: =IF($C16<=N$3,1," ") | O16: =IF($C16<=O$3,1," ") | P16: =IF($C16<=P$3,1," ") | Q16: =IF($C16<=Q$3,1," ") | R16: =IF($C16<=R$3,1," ") | S16: =IF($C16<=S$3,1," ") | T16: =IF($C16<=T$3,1," ") | ... BB16: =IF($C16<=BB$3,1," ") -> 1
B17: Data Analytics | C17: 46753 | D17: 3 | M17: =IF($C17<=M$3,1," ") | N17: =IF($C17<=N$3,1," ") | O17: =IF($C17<=O$3,1," ") | P17: =IF($C17<=P$3,1," ") | R17: =IF($C17<=R$3,1," ") | S17: =IF($C17<=S$3,1," ") | T17: =IF($C17<=T$3,1," ") | U17: =IF($C17<=U$3,1," ") | V17: =IF($C17<=V$3,1," ") | W17: =IF($C17<=W$3,1," ") | X17: =IF($C17<=X$3,1," ") | Y17: =IF($C17<=Y$3,1," ") | ... BB17: =IF($C17<=BB$3,1," ") -> 1
A20: Expenses | G20: =G26+G32+G56+G74 -> 113758 | H20: =H26+H32+H56+H74 -> 113758 | I20: =I26+I32+I56+I74 -> 174140.42 | J20: =J26+J32+J56+J74 -> 201961.67 | K20: =K26+K32+K56+K74 -> 214841.88 | L20: =L26+L32+L56+L74 -> 227722.08 | M20: =M26+M32+M56+M74 -> 302862.75 | N20: =N26+N32+N56+N74 -> 315323.42 | ... AP20: =AP26+AP32+AP56+AP74 -> 1685760.3
B22: Expenses less Staff | G22: =G20-SUM(G75:G79) -> 33952.229 | H22: =H20-SUM(H75:H79) -> 33952.229 | I22: =I20-SUM(I75:I79) -> 81969.646 | J22: =J20-SUM(J75:J79) -> 95880.271 | K22: =K20-SUM(K75:K79) -> 108760.48 | L22: =L20-SUM(L75:L79) -> 121640.69 | M22: =M20-SUM(M75:M79) -> 217389.69 | N22: =N20-SUM(N75:N79) -> 224080.02 | ... AP22: =AP20-SUM(AP75:AP79) -> 1062306.7
B23: Difference month to month | H23: =H22-G22 -> 0 | I23: =I22-H22 -> 48017.417 | J23: =J22-I22 -> 13910.625 | K23: =K22-J22 -> 12880.208 | L23: =L22-K22 -> 12880.208 | M23: =M22-L22 -> 95749 | N23: =N22-M22 -> 6690.3333 | O23: =O22-N22 -> 920 | ... AP23: =AP22-AO22 -> 41204.167
G24: =G84-G85 -> 2837.92 | H24: =H84-H85 -> 6867.31 | I24: =I84-I85 -> 6704.5683 | J24: =J84-J85 -> 10835.97 | K24: =K84-K85 -> 7900.8555 | L24: =L84-L85 -> 57452.096 | M24: =M84-M85 -> -27900
B26: Technology | C26: =SUM(C27:C31) -> 325000 | G26: =SUM(G27:G31) -> 7728.125 | H26: =SUM(H27:H31) -> 7728.125 | I26: =SUM(I27:I31) -> 7728.125 | J26: =SUM(J27:J31) -> 7728.125 | K26: =SUM(K27:K31) -> 7728.125 | L26: =SUM(L27:L31) -> 7728.125 | M26: =SUM(M27:M31) -> 7728.125 | N26: =SUM(N27:N31) -> 7728.125 | ... BB26: =SUM(BB27:BB31) -> 0
B27: IT department - development costs and staff (How many staff?) | C27: 75000 | D27: 10000 | E27: 5000 | F27: Set up // Monthly | Q27: =$D27 -> 10000 | R27: =$D27 -> 10000 | S27: =$D27 -> 10000 | T27: =$E27 -> 5000 | U27: =$E27 -> 5000 | V27: =$E27 -> 5000 | W27: =$E27 -> 5000 | X27: =$E27 -> 5000 | Y27: =$E27 -> 5000 | Z27: =$E27 -> 5000 | AA27: =$E27 -> 5000 | ... AP27: =$E27 -> 5000
B28: SEO Tools and Audit | C28: 100000 | D28: 40000 | E28: 5000 | F28: Set up // Monthly | S28: =$D28 -> 40000 | T28: =$E28 -> 5000 | U28: =$E28 -> 5000 | V28: =$E28 -> 5000 | W28: =$E28 -> 5000 | X28: =$E28 -> 5000 | Y28: =$E28 -> 5000 | Z28: =$E28 -> 5000 | AA28: =$E28 -> 5000 | ... AP28: =$E28 -> 5000
B29: Data analysis: HC Compliance | C29: 150000 | D29: 10000 | F29: Monthly | Y29: =$D29 -> 10000 | Z29: =$D29 -> 10000 | AA29: =$D29 -> 10000 | AB29: =$D29 -> 10000 | AC29: =$D29 -> 10000 | AD29: =$D29 -> 10000 | AE29: =$D29 -> 10000 | AF29: =$D29 -> 10000 | ... AP29: =$D29 -> 10000
B30: Staff | G30: =G79 -> 7728.125 | H30: =H79 -> 7728.125 | I30: =I79 -> 7728.125 | J30: =J79 -> 7728.125 | K30: =K79 -> 7728.125 | L30: =L79 -> 7728.125 | M30: =M79 -> 7728.125 | N30: =N79 -> 7728.125 | ... BB30: =BB79 -> 0
B32: Marketing and Development | C32: =SUM(C33:C45) -> 2805000 | G32: =SUM(G33:G47) -> 26224.104 | H32: =SUM(H33:H47) -> 26224.104 | I32: =SUM(I33:I47) -> 26224.104 | J32: =SUM(J33:J47) -> 26224.104 | K32: =SUM(K33:K47) -> 26224.104 | L32: =SUM(L33:L47) -> 26224.104 | M32: =SUM(M33:M47) -> 26224.104 | N32: =SUM(N33:N47) -> 26224.104 | ... BB32: =SUM(BB33:BB47) -> 0
A33: BD | B33: Brand Development | C33: 300000 | D33: 25000 | E33: For 9 months | T33: =$D33 -> 25000 | U33: =$D33 -> 25000 | V33: =$D33 -> 25000 | W33: =$D33 -> 25000 | X33: =$D33 -> 25000 | Y33: =$D33 -> 25000 | Z33: =$D33 -> 25000 | AA33: =$D33 -> 25000 | AB33: =$E33 -> For 9 months | AC33: =$E33 -> For 9 months | AD33: =$E33 -> For 9 months | AE33: =$E33 -> For 9 months | AF33: =$E33 -> For 9 months | AG33: =$E33 -> For 9 months | AH33: =$E33 -> For 9 months | AI33: =$E33 -> For 9 months | ... AK33: =$E33 -> For 9 months
A34: BD | B34: Content Production | C34: 140000 | D34: 10000 | E34: Monthly | U34: =$D34 -> 10000 | V34: =$D34 -> 10000 | W34: =$D34 -> 10000 | X34: =$D34 -> 10000 | Y34: =$D34 -> 10000 | Z34: =$D34 -> 10000 | AA34: =$D34 -> 10000 | AB34: =$D34 -> 10000 | ... AP34: =$D34 -> 10000
A35: BD | B35: Thought Leadership Content | C35: 180000 | D35: 30000 | E35: Quarterly | U35: =$D35 -> 30000 | X35: =$D35 -> 30000 | AA35: =$D35 -> 30000 | AD35: =$D35 -> 30000 | AG35: =$D35 -> 30000 | AJ35: =$D35 -> 30000 | AM35: =$D35 -> 30000 | AP35: =$D35 -> 30000
A36: BD | B36: Brand Collateral | C36: 20000 | D36: 1500 | E36: Monthly | V36: =$D36 -> 1500 | W36: =$D36 -> 1500 | X36: =$D36 -> 1500 | Y36: =$D36 -> 1500 | Z36: =$D36 -> 1500 | AA36: =$D36 -> 1500 | AB36: =$D36 -> 1500 | AC36: =$D36 -> 1500 | ... AP36: =$D36 -> 1500
A37: BD | B37: Digital Demand Generator | C37: 320000 | D37: 15000 | E37: Monthly | U37: =$D37 -> 15000 | V37: =$D37 -> 15000 | W37: =$D37 -> 15000 | X37: =$D37 -> 15000 | Y37: =$D37 -> 15000 | Z37: =$D37 -> 15000 | AA37: =$D37 -> 15000 | AB37: =$D37 -> 15000 | ... AP37: =$D37 -> 15000
A38: BD | B38: ABM Tools | C38: 200000 | D38: 10000 | E38: Monthly | U38: =$D38 -> 10000 | V38: =$D38 -> 10000 | W38: =$D38 -> 10000 | X38: =$D38 -> 10000 | Y38: =$D38 -> 10000 | Z38: =$D38 -> 10000 | AA38: =$D38 -> 10000 | AB38: =$D38 -> 10000 | ... AP38: =$D38 -> 10000
A39: BD | B39: Sales Enablement Collateral | C39: 200000 | D39: 8000 | E39: Monthly | S39: =$D39 -> 8000 | T39: =$D39 -> 8000 | U39: =$D39 -> 8000 | V39: =$D39 -> 8000 | W39: =$D39 -> 8000 | X39: =$D39 -> 8000 | Y39: =$D39 -> 8000 | Z39: =$D39 -> 8000 | ... AP39: =$D39 -> 8000
A40: BD | B40: Flagship Conf Booths - 3 | C40: 400000 | D40: =C40/3 -> 133333.33 | U40: =$D40 -> 133333.33 | W40: =$D40 -> 133333.33 | Y40: =$D40 -> 133333.33
A41: BD | B41: Roadshows - 5 Cities | C41: 200000 | D41: =C41/5 -> 40000 | E41: Every other month except Dec | T41: =$D41 -> 40000 | V41: =$D41 -> 40000 | X41: =$D41 -> 40000 | Z41: =$D41 -> 40000 | AB41: =$D41 -> 40000 | AF41: =$D41 -> 40000 | AH41: =$D41 -> 40000 | AJ41: =$D41 -> 40000 | AL41: =$D41 -> 40000 | AN41: =$D41 -> 40000
A42: BD | B42: Onsite Staffing and Travel | C42: 150000 | D42: =C42/5 -> 30000 | E42: Every other month except Dec | T42: =$D42 -> 30000 | V42: =$D42 -> 30000 | X42: =$D42 -> 30000 | Z42: =$D42 -> 30000 | AB42: =$D42 -> 30000 | AF42: =$D42 -> 30000 | AH42: =$D42 -> 30000 | AJ42: =$D42 -> 30000 | AL42: =$D42 -> 30000 | AN42: =$D42 -> 30000
A43: BD | B43: Single Marquee Sponsorship | C43: 300000 | D43: =C43 -> 300000 | E43: Annually | V43: =$D43 -> 300000 | AH43: =$D43 -> 300000
A44: BD | B44: Paid Search and Social | C44: 320000 | D44: 28000 | E44: Monthly | S44: =$D44 -> 28000 | T44: =$D44 -> 28000 | U44: =$D44 -> 28000 | V44: =$D44 -> 28000 | W44: =$D44 -> 28000 | X44: =$D44 -> 28000 | Y44: =$D44 -> 28000 | Z44: =$D44 -> 28000 | ... AP44: =$D44 -> 28000
A45: BD | B45: Organic Social Management | C45: 75000 | D45: =C45/12 -> 6250 | E45: Monthly | S45: =$D45 -> 6250 | T45: =$D45 -> 6250 | U45: =$D45 -> 6250 | V45: =$D45 -> 6250 | W45: =$D45 -> 6250 | X45: =$D45 -> 6250 | Y45: =$D45 -> 6250 | Z45: =$D45 -> 6250 | ... AP45: =$D45 -> 6250
A46: BD | B46: Staff | G46: =G76+G77 -> 26224.104 | H46: =H76+H77 -> 26224.104 | I46: =I76+I77 -> 26224.104 | J46: =J76+J77 -> 26224.104 | K46: =K76+K77 -> 26224.104 | L46: =L76+L77 -> 26224.104 | M46: =M76+M77 -> 26224.104 | N46: =N76+N77 -> 26224.104 | ... BB46: =BB76+BB77 -> 0
B48: Clinical Operations | C48: =SUM(C49:C51) -> 1125000 | G48: =SUM(G49:G55) -> 26224.104 | H48: =SUM(H49:H55) -> 26224.104 | I48: =SUM(I49:I55) -> 26224.104 | J48: =SUM(J49:J55) -> 26224.104 | K48: =SUM(K49:K55) -> 26224.104 | L48: =SUM(L49:L55) -> 26224.104 | M48: =SUM(M49:M55) -> 26224.104 | N48: =SUM(N49:N55) -> 26224.104 | ... AP48: =SUM(AP49:AP55) -> 234562.16
...

Sheet Staffing
A2: EMPLOYEES: | K2: 45658 | L2: 45689 | M2: 45717 | N2: 45748 | O2: 45778 | P2: 45809 | Q2: 45839 | R2: 45870 | S2: 45901 | T2: 45931 | U2: 45962 | V2: 45992 | W2: 46023 | X2: 46054 | Y2: 46082 | Z2: 46113 | AA2: 46143 | AB2: 46174 | AC2: 46204 | AD2: 46235 | AE2: 46266 | AF2: 46296 | AG2: 46327 | AH2: 46357 | AI2: 46388 | AJ2: 46419 | AK2: 46447 | AL2: 46478 | AM2: 46508 | AN2: 46539 | AO2: 46569 | AP2: 46600 | AQ2: 46631 | AR2: 46661 | AS2: 46692 | AT2: 46722
B3: Last | C3: First | D3: Title | E3: Department | G3: Salary | H3: Monthly | I3: Start Date
A4: 1 | B4: Loeb | C4: Yisroel | D4: CEO | E4: Executive | F4: G&A | G4: DRAW | H4: 15000 | I4: 45658 | K4: 2854 | L4: 1411 | M4: 6767 | N4: =3708+450000 -> 453708 | O4: 3336 | P4: 13259 | Q4: 10670 | R4: 1220 | W4: =IF(W$2>=$I4,$H4,0) -> 15000 | X4: =IF(X$2>=$I4,$H4,0) -> 15000 | Y4: =IF(Y$2>=$I4,$H4,0) -> 15000 | Z4: =IF(Z$2>=$I4,$H4,0) -> 15000 | AA4: =IF(AA$2>=$I4,$H4,0) -> 15000 | AB4: =IF(AB$2>=$I4,$H4,0) -> 15000 | AC4: =IF(AC$2>=$I4,$H4,0) -> 15000 | AD4: =IF(AD$2>=$I4,$H4,0) -> 15000 | ... AT4: =IF(AT$2>=$I4,$H4,0) -> 15000
A5: 2 | B5: Reintein | C5: Sam | D5: CFO | E5: Executive | F5: G&A | G5: 250000 | H5: =G5/12 -> 20833.333 | I5: 45658 | K5: 0 | L5: 0 | M5: 0 | N5: 0 | O5: 0 | P5: 0 | Q5: 0 | R5: 0 | S5: 0 | T5: 0 | U5: 0 | V5: 0 | W5: =IF(W$2>=$I5,$H5,0) -> 20833.333 | X5: =IF(X$2>=$I5,$H5,0) -> 20833.333 | Y5: =IF(Y$2>=$I5,$H5,0) -> 20833.333 | Z5: =IF(Z$2>=$I5,$H5,0) -> 20833.333 | AA5: =IF(AA$2>=$I5,$H5,0) -> 20833.333 | AB5: =IF(AB$2>=$I5,$H5,0) -> 20833.333 | AC5: =IF(AC$2>=$I5,$H5,0) -> 20833.333 | AD5: =IF(AD$2>=$I5,$H5,0) -> 20833.333 | ... AT5: =IF(AT$2>=$I5,$H5,0) -> 20833.333
A6: 3 | B6: Blech | C6: Benzion | D6: CTO | E6: Executive | F6: G&A | G6: 300000 | H6: =G6/12 -> 25000 | I6: 45658 | K6: 0 | L6: 0 | M6: 10000 | N6: 10000 | O6: 10000 | P6: 10000 | Q6: 10000 | R6: 10000 | S6: 10000 | T6: 10000 | U6: 10000 | V6: 10000 | W6: =IF(W$2>=$I6,$H6,0) -> 25000 | X6: =IF(X$2>=$I6,$H6,0) -> 25000 | Y6: =IF(Y$2>=$I6,$H6,0) -> 25000 | Z6: =IF(Z$2>=$I6,$H6,0) -> 25000 | AA6: =IF(AA$2>=$I6,$H6,0) -> 25000 | AB6: =IF(AB$2>=$I6,$H6,0) -> 25000 | AC6: =IF(AC$2>=$I6,$H6,0) -> 25000 | AD6: =IF(AD$2>=$I6,$H6,0) -> 25000 | ... AT6: =IF(AT$2>=$I6,$H6,0) -> 25000
A7: 4 | B7: Craft | C7: Sherry | D7: CCO | E7: Executive | F7: G&A | G7: 250000 | H7: =G7/12 -> 20833.333 | I7: 45658 | K7: 12500 | L7: 12500 | M7: 12500 | N7: 12500 | O7: 12500 | P7: 12500 | Q7: 12500 | R7: 12500 | S7: 12500 | T7: 12500 | U7: 12500 | V7: 12500 | W7: =IF(W$2>=$I7,$H7,0) -> 20833.333 | X7: =IF(X$2>=$I7,$H7,0) -> 20833.333 | Y7: =IF(Y$2>=$I7,$H7,0) -> 20833.333 | Z7: =IF(Z$2>=$I7,$H7,0) -> 20833.333 | AA7: =IF(AA$2>=$I7,$H7,0) -> 20833.333 | AB7: =IF(AB$2>=$I7,$H7,0) -> 20833.333 | AC7: =IF(AC$2>=$I7,$H7,0) -> 20833.333 | AD7: =IF(AD$2>=$I7,$H7,0) -> 20833.333 | ... AT7: =IF(AT$2>=$I7,$H7,0) -> 20833.333
B8: NEW | D8: CMO | E8: Executive | F8: G&A | G8: 300000 | H8: =G8/12 -> 25000 | I8: 45962 | Q8: =IF(Q$2>=$I8,$H8,0) -> 0 | R8: =IF(R$2>=$I8,$H8,0) -> 0 | S8: =IF(S$2>=$I8,$H8,0) -> 0 | T8: =IF(T$2>=$I8,$H8,0) -> 0 | W8: =IF(W$2>=$I8,$H8,0) -> 25000 | X8: =IF(X$2>=$I8,$H8,0) -> 25000 | Y8: =IF(Y$2>=$I8,$H8,0) -> 25000 | Z8: =IF(Z$2>=$I8,$H8,0) -> 25000 | AA8: =IF(AA$2>=$I8,$H8,0) -> 25000 | AB8: =IF(AB$2>=$I8,$H8,0) -> 25000 | AC8: =IF(AC$2>=$I8,$H8,0) -> 25000 | AD8: =IF(AD$2>=$I8,$H8,0) -> 25000 | ... AT8: =IF(AT$2>=$I8,$H8,0) -> 25000
B9: NEW | D9: COO | E9: Executive | F9: G&A | G9: 300000 | H9: =G9/12 -> 25000 | I9: 45962 | Q9: =IF(Q$2>=$I9,$H9,0) -> 0 | R9: =IF(R$2>=$I9,$H9,0) -> 0 | S9: =IF(S$2>=$I9,$H9,0) -> 0 | T9: =IF(T$2>=$I9,$H9,0) -> 0 | W9: =IF(W$2>=$I9,$H9,0) -> 25000 | X9: =IF(X$2>=$I9,$H9,0) -> 25000 | Y9: =IF(Y$2>=$I9,$H9,0) -> 25000 | Z9: =IF(Z$2>=$I9,$H9,0) -> 25000 | AA9: =IF(AA$2>=$I9,$H9,0) -> 25000 | AB9: =IF(AB$2>=$I9,$H9,0) -> 25000 | AC9: =IF(AC$2>=$I9,$H9,0) -> 25000 | AD9: =IF(AD$2>=$I9,$H9,0) -> 25000 | ... AT9: =IF(AT$2>=$I9,$H9,0) -> 25000
A10: 5 | B10: Cohen | C10: Nate | D10: Directors, Business Dev | E10: Business Dev | F10: Business Dev | G10: 200000 | H10: =G10/12 -> 16666.667 | I10: 45139 | K10: 16666.667 | L10: 16666.667 | M10: 16666.667 | N10: 16666.667 | O10: 16666.667 | P10: 16666.667 | Q10: 16666.667 | R10: 16666.667 | S10: 16666.667 | T10: 16666.667 | U10: 16666.667 | V10: 16666.667 | W10: =IF(W$2>=$I10,$H10,0) -> 16666.667 | X10: =IF(X$2>=$I10,$H10,0) -> 16666.667 | Y10: =IF(Y$2>=$I10,$H10,0) -> 16666.667 | Z10: =IF(Z$2>=$I10,$H10,0) -> 16666.667 | AA10: =IF(AA$2>=$I10,$H10,0) -> 16666.667 | AB10: =IF(AB$2>=$I10,$H10,0) -> 16666.667 | AC10: =IF(AC$2>=$I10,$H10,0) -> 16666.667 | AD10: =IF(AD$2>=$I10,$H10,0) -> 16666.667 | ... AT10: =IF(AT$2>=$I10,$H10,0) -> 16666.667
A11: 6 | B11: Dodson | C11: Danielle | D11: HR Director | E11: HR | F11: G&A | G11: 125000 | H11: =G11/12 -> 10416.667 | I11: 45627 | K11: 7916.6667 | L11: 7916.6667 | M11: 7916.6667 | N11: 7916.6667 | O11: 7916.6667 | P11: 7916.6667 | Q11: 7916.6667 | R11: 7916.6667 | S11: 7916.6667 | T11: 7916.6667 | U11: 7916.6667 | V11: 7916.6667 | W11: =IF(W$2>=$I11,$H11,0) -> 10416.667 | X11: =IF(X$2>=$I11,$H11,0) -> 10416.667 | Y11: =IF(Y$2>=$I11,$H11,0) -> 10416.667 | Z11: =IF(Z$2>=$I11,$H11,0) -> 10416.667 | AA11: =IF(AA$2>=$I11,$H11,0) -> 10416.667 | AB11: =IF(AB$2>=$I11,$H11,0) -> 10416.667 | AC11: =IF(AC$2>=$I11,$H11,0) -> 10416.667 | AD11: =IF(AD$2>=$I11,$H11,0) -> 10416.667 | ... AT11: =IF(AT$2>=$I11,$H11,0) -> 10416.667
A12: 7 | B12: Kulfan | C12: Jaclyn | D12: Ops Director | E12: Operations | F12: G&A | G12: 135000 | H12: =G12/12 -> 11250 | I12: 45741 | K12: 0 | L12: 0 | M12: 0 | N12: 11250 | O12: 11250 | P12: 11250 | Q12: 11250 | R12: 11250 | S12: 11250 | T12: 11250 | U12: 11250 | V12: 11250 | W12: =IF(W$2>=$I12,$H12,0) -> 11250 | X12: =IF(X$2>=$I12,$H12,0) -> 11250 | Y12: =IF(Y$2>=$I12,$H12,0) -> 11250 | Z12: =IF(Z$2>=$I12,$H12,0) -> 11250 | AA12: =IF(AA$2>=$I12,$H12,0) -> 11250 | AB12: =IF(AB$2>=$I12,$H12,0) -> 11250 | AC12: =IF(AC$2>=$I12,$H12,0) -> 11250 | AD12: =IF(AD$2>=$I12,$H12,0) -> 11250 | ... AT12: =IF(AT$2>=$I12,$H12,0) -> 11250
A13: 8 | B13: Kawaski | C13: Bailey | D13: Office Manager | E13: Finance Admin | F13: G&A | G13: 44000 | H13: =G13/12 -> 3666.6667 | I13: 45931 | K13: 0 | L13: 0 | M13: 0 | N13: 0 | O13: 0 | P13: 0 | Q13: 0 | R13: 0 | S13: 0 | T13: 3666.6667 | U13: 3666.6667 | V13: 3666.6667 | W13: =IF(W$2>=$I13,$H13,0) -> 3666.6667 | X13: =IF(X$2>=$I13,$H13,0) -> 3666.6667 | Y13: =IF(Y$2>=$I13,$H13,0) -> 3666.6667 | Z13: =IF(Z$2>=$I13,$H13,0) -> 3666.6667 | AA13: =IF(AA$2>=$I13,$H13,0) -> 3666.6667 | AB13: =IF(AB$2>=$I13,$H13,0) -> 3666.6667 | AC13: =IF(AC$2>=$I13,$H13,0) -> 3666.6667 | AD13: =IF(AD$2>=$I13,$H13,0) -> 3666.6667 | ... AT13: =IF(AT$2>=$I13,$H13,0) -> 3666.6667
A14: 9 | B14: Kluger | C14: Kasiah | D14: Mgr, Provider Recruiting | E14: Clinical Ops | F14: Clinical Ops | G14: 70000 | H14: =G14/12 -> 5833.3333 | I14: 45444 | K14: 5833.3333 | L14: 5833.3333 | M14: 5833.3333 | N14: 5833.3333 | O14: 5833.3333 | P14: 5833.3333 | Q14: 5833.3333 | R14: 5833.3333 | S14: 5833.3333 | T14: 5833.3333 | U14: 5833.3333 | V14: 5833.3333 | W14: =IF(W$2>=$I14,$H14,0) -> 5833.3333 | X14: =IF(X$2>=$I14,$H14,0) -> 5833.3333 | Y14: =IF(Y$2>=$I14,$H14,0) -> 5833.3333 | Z14: =IF(Z$2>=$I14,$H14,0) -> 5833.3333 | AA14: =IF(AA$2>=$I14,$H14,0) -> 5833.3333 | AB14: =IF(AB$2>=$I14,$H14,0) -> 5833.3333 | AC14: =IF(AC$2>=$I14,$H14,0) -> 5833.3333 | AD14: =IF(AD$2>=$I14,$H14,0) -> 5833.3333 | ... AT14: =IF(AT$2>=$I14,$H14,0) -> 5833.3333
A15: 10 | B15: Aviva | C15: David | D15: Mgr, Provider Recruiting | E15: Clinical Ops | F15: Clinical Ops | G15: 82500 | H15: =G15/12 -> 6875 | I15: 45335 | K15: 6875 | L15: 6875 | M15: 6875 | N15: 6875 | O15: 6875 | P15: 6875 | Q15: 6875 | R15: 6875 | S15: 6875 | T15: 6875 | U15: 6875 | V15: 6875 | W15: =IF(W$2>=$I15,$H15,0) -> 6875 | X15: =IF(X$2>=$I15,$H15,0) -> 6875 | Y15: =IF(Y$2>=$I15,$H15,0) -> 6875 | Z15: =IF(Z$2>=$I15,$H15,0) -> 6875 | AA15: =IF(AA$2>=$I15,$H15,0) -> 6875 | AB15: =IF(AB$2>=$I15,$H15,0) -> 6875 | AC15: =IF(AC$2>=$I15,$H15,0) -> 6875 | AD15: =IF(AD$2>=$I15,$H15,0) -> 6875 | ... AT15: =IF(AT$2>=$I15,$H15,0) -> 6875
A16: 11 | B16: Gallegos | C16: Martha | D16: Case Mgr, PI | E16: Clinical Ops | F16: PI | G16: 57000 | H16: =G16/12 -> 4750 | I16: 45839 | K16: 0 | L16: 0 | M16: 0 | N16: 0 | O16: 0 | P16: 0 | Q16: 4750 | R16: 4750 | S16: 4750 | T16: 4750 | U16: 4750 | V16: 4750 | W16: =IF(W$2>=$I16,$H16,0) -> 4750 | X16: =IF(X$2>=$I16,$H16,0) -> 4750 | Y16: =IF(Y$2>=$I16,$H16,0) -> 4750 | Z16: =IF(Z$2>=$I16,$H16,0) -> 4750 | AA16: =IF(AA$2>=$I16,$H16,0) -> 4750 | AB16: =IF(AB$2>=$I16,$H16,0) -> 4750 | AC16: =IF(AC$2>=$I16,$H16,0) -> 4750 | AD16: =IF(AD$2>=$I16,$H16,0) -> 4750 | ... AT16: =IF(AT$2>=$I16,$H16,0) -> 4750
A17: 12 | B17: Zuckerberg | C17: Beth | D17: Biz Dev, PI | E17: Business Dev | F17: PI | G17: 125000 | H17: =G17/12 -> 10416.667 | I17: 45754 | K17: 0 | L17: 0 | M17: 0 | N17: 0 | O17: 10416.667 | P17: 10416.667 | Q17: 10416.667 | R17: 10416.667 | S17: 10416.667 | T17: 10416.667 | U17: 10416.667 | V17: 10416.667 | W17: =IF(W$2>=$I17,$H17,0) -> 10416.667 | X17: =IF(X$2>=$I17,$H17,0) -> 10416.667 | Y17: =IF(Y$2>=$I17,$H17,0) -> 10416.667 | Z17: =IF(Z$2>=$I17,$H17,0) -> 10416.667 | AA17: =IF(AA$2>=$I17,$H17,0) -> 10416.667 | AB17: =IF(AB$2>=$I17,$H17,0) -> 10416.667 | AC17: =IF(AC$2>=$I17,$H17,0) -> 10416.667 | AD17: =IF(AD$2>=$I17,$H17,0) -> 10416.667 | ... AT17: =IF(AT$2>=$I17,$H17,0) -> 10416.667
A18: 13 | B18: Rafael | C18: Ayden | D18: Biz Dev, Jr Assoc | E18: Business Dev | F18: PI | G18: 55000 | H18: =G18/12 -> 4583.3333 | I18: 45817 | K18: 0 | L18: 0 | M18: 0 | N18: 0 | O18: 0 | P18: 0 | Q18: 4583.3333 | R18: 4583.3333 | S18: 4583.3333 | T18: 4583.3333 | U18: 4583.3333 | V18: 4583.3333 | W18: =IF(W$2>=$I18,$H18,0) -> 4583.3333 | X18: =IF(X$2>=$I18,$H18,0) -> 4583.3333 | Y18: =IF(Y$2>=$I18,$H18,0) -> 4583.3333 | Z18: =IF(Z$2>=$I18,$H18,0) -> 4583.3333 | AA18: =IF(AA$2>=$I18,$H18,0) -> 4583.3333 | AB18: =IF(AB$2>=$I18,$H18,0) -> 4583.3333 | AC18: =IF(AC$2>=$I18,$H18,0) -> 4583.3333 | AD18: =IF(AD$2>=$I18,$H18,0) -> 4583.3333 | ... AT18: =IF(AT$2>=$I18,$H18,0) -> 4583.3333
A19: 14 | B19: Rincon | C19: Ashlee | D19: Director, Clinical Ops | E19: Clinical Ops | F19: PI | G19: 125000 | H19: =G19/12 -> 10416.667 | I19: 45784 | K19: 0 | L19: 0 | M19: 0 | N19: 0 | O19: 0 | P19: 10416.667 | Q19: 10416.667 | R19: 10416.667 | S19: 10416.667 | T19: 10416.667 | U19: 10416.667 | V19: 10416.667 | W19: =IF(W$2>=$I19,$H19,0) -> 10416.667 | X19: =IF(X$2>=$I19,$H19,0) -> 10416.667 | Y19: =IF(Y$2>=$I19,$H19,0) -> 10416.667 | Z19: =IF(Z$2>=$I19,$H19,0) -> 10416.667 | AA19: =IF(AA$2>=$I19,$H19,0) -> 10416.667 | AB19: =IF(AB$2>=$I19,$H19,0) -> 10416.667 | AC19: =IF(AC$2>=$I19,$H19,0) -> 10416.667 | AD19: =IF(AD$2>=$I19,$H19,0) -> 10416.667 | ... AT19: =IF(AT$2>=$I19,$H19,0) -> 10416.667
A20: 15 | B20: Locke | C20: Ashley | D20: Clinical Ops Mgr | E20: Clinical Ops | F20: PI | G20: 48000 | H20: =G20/12 -> 4000 | I20: 45717 | K20: 0 | L20: 0 | M20: 4000 | N20: 4000 | O20: 4000 | P20: 4000 | Q20: 4000 | R20: 4000 | S20: 4000 | T20: 4000 | U20: 4000 | V20: 4000 | W20: =IF(W$2>=$I20,$H20,0) -> 4000 | X20: =IF(X$2>=$I20,$H20,0) -> 4000 | Y20: =IF(Y$2>=$I20,$H20,0) -> 4000 | Z20: =IF(Z$2>=$I20,$H20,0) -> 4000 | AA20: =IF(AA$2>=$I20,$H20,0) -> 4000 | AB20: =IF(AB$2>=$I20,$H20,0) -> 4000 | AC20: =IF(AC$2>=$I20,$H20,0) -> 4000 | AD20: =IF(AD$2>=$I20,$H20,0) -> 4000 | ... AT20: =IF(AT$2>=$I20,$H20,0) -> 4000
A21: 16 | B21: Chapman | C21: Chelsea | D21: Clinical Care Coordinator | E21: Clinical Ops | F21: PI | G21: 53000 | H21: =G21/12 -> 4416.6667 | I21: 45708 | K21: 0 | L21: 0 | M21: 4416.6667 | N21: 4416.6667 | O21: 4416.6667 | P21: 4416.6667 | Q21: 4416.6667 | R21: 4416.6667 | S21: 4416.6667 | T21: 4416.6667 | U21: 4416.6667 | V21: 4416.6667 | W21: =IF(W$2>=$I21,$H21,0) -> 4416.6667 | X21: =IF(X$2>=$I21,$H21,0) -> 4416.6667 | Y21: =IF(Y$2>=$I21,$H21,0) -> 4416.6667 | Z21: =IF(Z$2>=$I21,$H21,0) -> 4416.6667 | AA21: =IF(AA$2>=$I21,$H21,0) -> 4416.6667 | AB21: =IF(AB$2>=$I21,$H21,0) -> 4416.6667 | AC21: =IF(AC$2>=$I21,$H21,0) -> 4416.6667 | AD21: =IF(AD$2>=$I21,$H21,0) -> 4416.6667 | ... AT21: =IF(AT$2>=$I21,$H21,0) -> 4416.6667
... A24: 21 | B24: Kanter | C24: Yishai | D24: IT Solutions Engineer | E24: Technolgy | F24: Technology | G24: 75000 | H24: =G24/12 -> 6250 | I24: 45233 | K24: 6250 | L24: 6250 | M24: 6250 | N24: 6250 | O24: 6250 | P24: 6250 | Q24: 6250 | R24: 6250 | S24: 6250 | T24: 6250 | U24: 6250 | V24: 6250 | W24: =IF(W$2>=$I24,$H24,0) -> 6250 | X24: =IF(X$2>=$I24,$H24,0) -> 6250 | Y24: =IF(Y$2>=$I24,$H24,0) -> 6250 | Z24: =IF(Z$2>=$I24,$H24,0) -> 6250 | AA24: =IF(AA$2>=$I24,$H24,0) -> 6250 | AB24: =IF(AB$2>=$I24,$H24,0) -> 6250 | AC24: =IF(AC$2>=$I24,$H24,0) -> 6250 | AD24: =IF(AD$2>=$I24,$H24,0) -> 6250 | ... AT24: =IF(AT$2>=$I24,$H24,0) -> 6250
A25: 1 | D25: QA | E25: Clinical Ops | F25: SaaS | G25: 75000 | H25: =G25/12 -> 6250 | I25: 46143 | Q25: =IF(Q$2>=$I25,$H25,0) -> 0 | R25: =IF(R$2>=$I25,$H25,0) -> 0 | S25: =IF(S$2>=$I25,$H25,0) -> 0 | T25: =IF(T$2>=$I25,$H25,0) -> 0 | U25: =IF(U$2>=$I25,$H25,0) -> 0 | V25: =IF(V$2>=$I25,$H25,0) -> 0 | W25: =IF(W$2>=$I25,$H25,0) -> 0 | X25: =IF(X$2>=$I25,$H25,0) -> 0 | ... AT25: =IF(AT$2>=$I25,$H25,0) -> 6250
A26: 2 | D26: QA | E26: Clinical Ops | F26: SaaS | G26: 75000 | H26: =G26/12 -> 6250 | I26: 46692 | Q26: =IF(Q$2>=$I26,$H26,0) -> 0 | R26: =IF(R$2>=$I26,$H26,0) -> 0 | S26: =IF(S$2>=$I26,$H26,0) -> 0 | T26: =IF(T$2>=$I26,$H26,0) -> 0 | W26: =IF(W$2>=$I26,$H26,0) -> 0 | X26: =IF(X$2>=$I26,$H26,0) -> 0 | Y26: =IF(Y$2>=$I26,$H26,0) -> 0 | Z26: =IF(Z$2>=$I26,$H26,0) -> 0 | AA26: =IF(AA$2>=$I26,$H26,0) -> 0 | AB26: =IF(AB$2>=$I26,$H26,0) -> 0 | AC26: =IF(AC$2>=$I26,$H26,0) -> 0 | AD26: =IF(AD$2>=$I26,$H26,0) -> 0 | ... AT26: =IF(AT$2>=$I26,$H26,0) -> 6250
A27: 3 | D27: Provider Liaison/Training | E27: Clinical Ops | F27: Clinical Ops | G27: 125000 | H27: =G27/12 -> 10416.667 | I27: 45992 | Q27: =IF(Q$2>=$I27,$H27,0) -> 0 | R27: =IF(R$2>=$I27,$H27,0) -> 0 | S27: =IF(S$2>=$I27,$H27,0) -> 0 | T27: =IF(T$2>=$I27,$H27,0) -> 0 | W27: =IF(W$2>=$I27,$H27,0) -> 10416.667 | X27: =IF(X$2>=$I27,$H27,0) -> 10416.667 | Y27: =IF(Y$2>=$I27,$H27,0) -> 10416.667 | Z27: =IF(Z$2>=$I27,$H27,0) -> 10416.667 | AA27: =IF(AA$2>=$I27,$H27,0) -> 10416.667 | AB27: =IF(AB$2>=$I27,$H27,0) -> 10416.667 | AC27: =IF(AC$2>=$I27,$H27,0) -> 10416.667 | AD27: =IF(AD$2>=$I27,$H27,0) -> 10416.667 | ... AT27: =IF(AT$2>=$I27,$H27,0) -> 10416.667
A28: 4 | D28: Provider Liaison/Training | E28: Clinical Ops | F28: Clinical Ops | G28: 125000 | H28: =G28/12 -> 10416.667 | I28: 46174 | Q28: =IF(Q$2>=$I28,$H28,0) -> 0 | R28: =IF(R$2>=$I28,$H28,0) -> 0 | S28: =IF(S$2>=$I28,$H28,0) -> 0 | T28: =IF(T$2>=$I28,$H28,0) -> 0 | W28: =IF(W$2>=$I28,$H28,0) -> 0 | X28: =IF(X$2>=$I28,$H28,0) -> 0 | Y28: =IF(Y$2>=$I28,$H28,0) -> 0 | Z28: =IF(Z$2>=$I28,$H28,0) -> 0 | AA28: =IF(AA$2>=$I28,$H28,0) -> 0 | AB28: =IF(AB$2>=$I28,$H28,0) -> 10416.667 | AC28: =IF(AC$2>=$I28,$H28,0) -> 10416.667 | AD28: =IF(AD$2>=$I28,$H28,0) -> 10416.667 | ... AT28: =IF(AT$2>=$I28,$H28,0) -> 10416.667
A29: 5 | D29: Provider Liaison/Training | E29: Clinical Ops | F29: Clinical Ops | G29: 125000 | H29: =G29/12 -> 10416.667 | I29: 46266 | Q29: =IF(Q$2>=$I29,$H29,0) -> 0 | R29: =IF(R$2>=$I29,$H29,0) -> 0 | S29: =IF(S$2>=$I29,$H29,0) -> 0 | T29: =IF(T$2>=$I29,$H29,0) -> 0 | W29: =IF(W$2>=$I29,$H29,0) -> 0 | X29: =IF(X$2>=$I29,$H29,0) -> 0 | Y29: =IF(Y$2>=$I29,$H29,0) -> 0 | Z29: =IF(Z$2>=$I29,$H29,0) -> 0 | AA29: =IF(AA$2>=$I29,$H29,0) -> 0 | AB29: =IF(AB$2>=$I29,$H29,0) -> 0 | AC29: =IF(AC$2>=$I29,$H29,0) -> 0 | AD29: =IF(AD$2>=$I29,$H29,0) -> 0 | ... AT29: =IF(AT$2>=$I29,$H29,0) -> 10416.667
A30: 6 | D30: Provider Liaison/Training | E30: Clinical Ops | F30: Clinical Ops | G30: 125000 | H30: =G30/12 -> 10416.667 | I30: 46419 | Q30: =IF(Q$2>=$I30,$H30,0) -> 0 | R30: =IF(R$2>=$I30,$H30,0) -> 0 | S30: =IF(S$2>=$I30,$H30,0) -> 0 | T30: =IF(T$2>=$I30,$H30,0) -> 0 | W30: =IF(W$2>=$I30,$H30,0) -> 0 | X30: =IF(X$2>=$I30,$H30,0) -> 0 | Y30: =IF(Y$2>=$I30,$H30,0) -> 0 | Z30: =IF(Z$2>=$I30,$H30,0) -> 0 | AA30: =IF(AA$2>=$I30,$H30,0) -> 0 | AB30: =IF(AB$2>=$I30,$H30,0) -> 0 | AC30: =IF(AC$2>=$I30,$H30,0) -> 0 | AD30: =IF(AD$2>=$I30,$H30,0) -> 0 | ... AT30: =IF(AT$2>=$I30,$H30,0) -> 10416.667
A31: 7 | D31: Provider Recruiting | E31: Clinical Ops | F31: Clinical Ops | G31: 90000 | H31: =G31/12 -> 7500 | I31: 45962 | Q31: =IF(Q$2>=$I31,$H31,0) -> 0 | R31: =IF(R$2>=$I31,$H31,0) -> 0 | S31: =IF(S$2>=$I31,$H31,0) -> 0 | T31: =IF(T$2>=$I31,$H31,0) -> 0 | W31: =IF(W$2>=$I31,$H31,0) -> 7500 | X31: =IF(X$2>=$I31,$H31,0) -> 7500 | Y31: =IF(Y$2>=$I31,$H31,0) -> 7500 | Z31: =IF(Z$2>=$I31,$H31,0) -> 7500 | AA31: =IF(AA$2>=$I31,$H31,0) -> 7500 | AB31: =IF(AB$2>=$I31,$H31,0) -> 7500 | AC31: =IF(AC$2>=$I31,$H31,0) -> 7500 | AD31: =IF(AD$2>=$I31,$H31,0) -> 7500 | ... AT31: =IF(AT$2>=$I31,$H31,0) -> 7500
A32: 8 | D32: Provider Recruiting | E32: Clinical Ops | F32: Clinical Ops | G32: 90000 | H32: =G32/12 -> 7500 | I32: 46143 | Q32: =IF(Q$2>=$I32,$H32,0) -> 0 | R32: =IF(R$2>=$I32,$H32,0) -> 0 | S32: =IF(S$2>=$I32,$H32,0) -> 0 | T32: =IF(T$2>=$I32,$H32,0) -> 0 | W32: =IF(W$2>=$I32,$H32,0) -> 0 | X32: =IF(X$2>=$I32,$H32,0) -> 0 | Y32: =IF(Y$2>=$I32,$H32,0) -> 0 | Z32: =IF(Z$2>=$I32,$H32,0) -> 0 | AA32: =IF(AA$2>=$I32,$H32,0) -> 7500 | AB32: =IF(AB$2>=$I32,$H32,0) -> 7500 | AC32: =IF(AC$2>=$I32,$H32,0) -> 7500 | AD32: =IF(AD$2>=$I32,$H32,0) -> 7500 | ... AT32: =IF(AT$2>=$I32,$H32,0) -> 7500
A33: 9 | D33: Provider Recruiting | E33: Clinical Ops | F33: Clinical Ops | G33: 90000 | H33: =G33/12 -> 7500 | I33: 46235 | Q33: =IF(Q$2>=$I33,$H33,0) -> 0 | R33: =IF(R$2>=$I33,$H33,0) -> 0 | S33: =IF(S$2>=$I33,$H33,0) -> 0 | T33: =IF(T$2>=$I33,$H33,0) -> 0 | U33: =IF(U$2>=$I33,$H33,0) -> 0 | V33: =IF(V$2>=$I33,$H33,0) -> 0 | W33: =IF(W$2>=$I33,$H33,0) -> 0 | X33: =IF(X$2>=$I33,$H33,0) -> 0 | ... AT33: =IF(AT$2>=$I33,$H33,0) -> 7500
A34: 10 | D34: Provider Recruiting | E34: Clinical Ops | F34: Clinical Ops | G34: 90000 | H34: =G34/12 -> 7500 | I34: 46388 | Q34: =IF(Q$2>=$I34,$H34,0) -> 0 | R34: =IF(R$2>=$I34,$H34,0) -> 0 | S34: =IF(S$2>=$I34,$H34,0) -> 0 | T34: =IF(T$2>=$I34,$H34,0) -> 0 | U34: =IF(U$2>=$I34,$H34,0) -> 0 | V34: =IF(V$2>=$I34,$H34,0) -> 0 | W34: =IF(W$2>=$I34,$H34,0) -> 0 | X34: =IF(X$2>=$I34,$H34,0) -> 0 | ... AT34: =IF(AT$2>=$I34,$H34,0) -> 7500
A35: 11 | D35: Subscrptions | E35: Clinical Ops | F35: Clinical Ops | G35: 75000 | H35: =G35/12 -> 6250 | I35: 46813 | Q35: =IF(Q$2>=$I35,$H35,0) -> 0 | R35: =IF(R$2>=$I35,$H35,0) -> 0 | S35: =IF(S$2>=$I35,$H35,0) -> 0 | T35: =IF(T$2>=$I35,$H35,0) -> 0 | U35: =IF(U$2>=$I35,$H35,0) -> 0 | V35: =IF(V$2>=$I35,$H35,0) -> 0 | W35: =IF(W$2>=$I35,$H35,0) -> 0 | X35: =IF(X$2>=$I35,$H35,0) -> 0 | ... AT35: =IF(AT$2>=$I35,$H35,0) -> 0
A36: 12 | D36: Subscrptions | E36: Clinical Ops | F36: Clinical Ops | G36: 75000 | H36: =G36/12 -> 6250 | I36: 46813 | Q36: =IF(Q$2>=$I36,$H36,0) -> 0 | R36: =IF(R$2>=$I36,$H36,0) -> 0 | S36: =IF(S$2>=$I36,$H36,0) -> 0 | T36: =IF(T$2>=$I36,$H36,0) -> 0 | U36: =IF(U$2>=$I36,$H36,0) -> 0 | V36: =IF(V$2>=$I36,$H36,0) -> 0 | W36: =IF(W$2>=$I36,$H36,0) -> 0 | X36: =IF(X$2>=$I36,$H36,0) -> 0 | ... AT36: =IF(AT$2>=$I36,$H36,0) -> 0
A37: 13 | D37: Subscrptions | E37: Clinical Ops | F37: Clinical Ops | G37: 75000 | H37: =G37/12 -> 6250 | I37: 46813 | Q37: =IF(Q$2>=$I37,$H37,0) -> 0 | R37: =IF(R$2>=$I37,$H37,0) -> 0 | S37: =IF(S$2>=$I37,$H37,0) -> 0 | T37: =IF(T$2>=$I37,$H37,0) -> 0 | U37: =IF(U$2>=$I37,$H37,0) -> 0 | V37: =IF(V$2>=$I37,$H37,0) -> 0 | W37: =IF(W$2>=$I37,$H37,0) -> 0 | X37: =IF(X$2>=$I37,$H37,0) -> 0 | ... AT37: =IF(AT$2>=$I37,$H37,0) -> 0
A38: 14 | D38: Med-legal Clinical Manager | E38: Clinical Ops | F38: PI | G38: 70000 | H38: =G38/12 -> 5833.3333 | J38: 2 | Q38: =IF(Worksheet!M$306>=$J38,Staffing!$H38,0) -> 0 | R38: =IF(Worksheet!N$306>=$J38,Staffing!$H38,0) -> 0 | S38: =IF(Worksheet!O$306>=$J38,Staffing!$H38,0) -> 0 | T38: =IF(Worksheet!P$306>=$J38,Staffing!$H38,0) -> 0 | U38: =IF(Worksheet!Q$306>=$J38,Staffing!$H38,0) -> 0 | V38: =IF(Worksheet!R$306>=$J38,Staffing!$H38,0) -> 0 | W38: =IF(Worksheet!S$306>=$J38,Staffing!$H38,0) -> 0 | X38: =IF(Worksheet!T$306>=$J38,Staffing!$H38,0) -> 0 | ... AT38: =IF(Worksheet!AP$306>=$J38,Staffing!$H38,0) -> 5833.3333
